<?xml version="1.0" ?>
<!-- =================================================================================== -->
<!-- |    This document was autogenerated by xacro from mmint_panda.urdf.xacro         | -->
<!-- |    EDITING THIS FILE BY HAND IS NOT RECOMMENDED                                 | -->
<!-- =================================================================================== -->
<robot name="panda">
  <material name="blue">
    <color rgba="0.0 0.0 0.8 1.0"/>
  </material>
  <material name="green">
    <color rgba="0.0 0.8 0.0 1.0"/>
  </material>
  <material name="grey">
    <color rgba="0.2 0.2 0.2 1.0"/>
  </material>
  <material name="orange">
    <color rgba="1.0 0.4235294117647059 0.0392156862745098 1.0"/>
  </material>
  <material name="brown">
    <color rgba="0.8705882352941177 0.8117647058823529 0.7647058823529411 1.0"/>
  </material>
  <material name="red">
    <color rgba="0.8 0.0 0.0 1.0"/>
  </material>
  <material name="white">
    <color rgba="1.0 1.0 1.0 1.0"/>
  </material>
  <material name="black">
    <color rgba="0.0 0.0 0.0 1.0"/>
  </material>
  <material name="light_grey">
    <color rgba="0.8 0.8 0.8 1.0"/>
  </material>
  <material name="trans_grey">
    <color rgba="0.2 0.2 0.2 0.5"/>
  </material>
  <!-- box shaped table as base for the 2 Pandas -->
  <link name="base">
    <visual>
      <origin rpy="0 0 0" xyz="0 0 0.3"/>
      <geometry>
        <box size="0.9 1.215 0.6"/>
      </geometry>
      <material name="light_grey"/>
    </visual>
    <collision>
      <origin rpy="0 0 0" xyz="0 0 0.3"/>
      <geometry>
        <box size="0.9 1.215 0.6"/>
      </geometry>
    </collision>
  </link>
  <link name="tabletop"/>
  <joint name="world_to_table" type="fixed">
    <origin rpy="0 0 0" xyz="0 0 0.6"/>
    <parent link="base"/>
    <child link="tabletop"/>
  </joint>
  <joint name="panda_1_joint_base" type="fixed">
    <parent link="base"/>
    <child link="panda_1_link0"/>
    <origin rpy="0.0 0.0 -1.57079633" xyz="0 0.4425 0.6"/>
  </joint>
  <!-- sub-link defining detailed meshes for collision with environment -->
  <link name="panda_1_link0">
    <visual>
      <geometry>
        <mesh filename="package://franka_description/meshes/visual/link0.dae"/>
      </geometry>
    </visual>
    <collision>
      <geometry>
        <mesh filename="package://franka_description/meshes/collision/link0.stl"/>
      </geometry>
    </collision>
  </link>
  <!-- sub-link defining coarse geometries of real robot's internal self-collision -->
  <link name="panda_1_link0_sc">
    <collision>
      <origin rpy="0 1.5707963267948966 0" xyz="-0.075 0 0.06"/>
      <geometry>
        <cylinder length="0.03" radius="0.06"/>
      </geometry>
    </collision>
    <collision>
      <origin xyz="-0.06 0 0.06"/>
      <geometry>
        <sphere radius="0.06"/>
      </geometry>
    </collision>
    <collision>
      <origin xyz="-0.09 0 0.06"/>
      <geometry>
        <sphere radius="0.06"/>
      </geometry>
    </collision>
  </link>
  <!-- fixed joint between both sub-links -->
  <joint name="panda_1_link0_sc_joint" type="fixed">
    <origin rpy="0 0 0"/>
    <parent link="panda_1_link0"/>
    <child link="panda_1_link0_sc"/>
  </joint>
  <!-- sub-link defining detailed meshes for collision with environment -->
  <link name="panda_1_link1">
    <visual>
      <geometry>
        <mesh filename="package://franka_description/meshes/visual/link1.dae"/>
      </geometry>
    </visual>
    <collision>
      <geometry>
        <mesh filename="package://franka_description/meshes/collision/link1.stl"/>
      </geometry>
    </collision>
  </link>
  <!-- sub-link defining coarse geometries of real robot's internal self-collision -->
  <link name="panda_1_link1_sc">
    <collision>
      <origin rpy="0 0 0" xyz="0 0 -0.1915"/>
      <geometry>
        <cylinder length="0.283" radius="0.06"/>
      </geometry>
    </collision>
    <collision>
      <origin xyz="0 0 -0.05000000000000002"/>
      <geometry>
        <sphere radius="0.06"/>
      </geometry>
    </collision>
    <collision>
      <origin xyz="0 0 -0.33299999999999996"/>
      <geometry>
        <sphere radius="0.06"/>
      </geometry>
    </collision>
  </link>
  <!-- fixed joint between both sub-links -->
  <joint name="panda_1_link1_sc_joint" type="fixed">
    <origin rpy="0 0 0"/>
    <parent link="panda_1_link1"/>
    <child link="panda_1_link1_sc"/>
  </joint>
  <joint name="panda_1_joint1" type="revolute">
    <origin rpy="0 0 0" xyz="0 0 0.333"/>
    <parent link="panda_1_link0"/>
    <child link="panda_1_link1"/>
    <axis xyz="0 0 1"/>
    <limit effort="87.0" lower="-2.8973" upper="2.8973" velocity="2.175"/>
    <safety_controller k_position="100.0" k_velocity="40.0" soft_lower_limit="-2.8973" soft_upper_limit="2.8973"/>
    <dynamics D="1" K="7000" damping="0.003" friction="0.0" mu_coulomb="0" mu_viscous="16"/>
  </joint>
  <!-- sub-link defining detailed meshes for collision with environment -->
  <link name="panda_1_link2">
    <visual>
      <geometry>
        <mesh filename="package://franka_description/meshes/visual/link2.dae"/>
      </geometry>
    </visual>
    <collision>
      <geometry>
        <mesh filename="package://franka_description/meshes/collision/link2.stl"/>
      </geometry>
    </collision>
  </link>
  <!-- sub-link defining coarse geometries of real robot's internal self-collision -->
  <link name="panda_1_link2_sc">
    <collision>
      <origin rpy="0 0 0" xyz="0 0 0"/>
      <geometry>
        <cylinder length="0.12" radius="0.06"/>
      </geometry>
    </collision>
    <collision>
      <origin xyz="0 0 0.06"/>
      <geometry>
        <sphere radius="0.06"/>
      </geometry>
    </collision>
    <collision>
      <origin xyz="0 0 -0.06"/>
      <geometry>
        <sphere radius="0.06"/>
      </geometry>
    </collision>
  </link>
  <!-- fixed joint between both sub-links -->
  <joint name="panda_1_link2_sc_joint" type="fixed">
    <origin rpy="0 0 0"/>
    <parent link="panda_1_link2"/>
    <child link="panda_1_link2_sc"/>
  </joint>
  <joint name="panda_1_joint2" type="revolute">
    <origin rpy="-1.5707963267948966 0 0" xyz="0 0 0"/>
    <parent link="panda_1_link1"/>
    <child link="panda_1_link2"/>
    <axis xyz="0 0 1"/>
    <limit effort="87.0" lower="-1.7628" upper="1.7628" velocity="2.175"/>
    <safety_controller k_position="100.0" k_velocity="40.0" soft_lower_limit="-1.7628" soft_upper_limit="1.7628"/>
    <dynamics D="1" K="7000" damping="0.003" friction="0.0" mu_coulomb="0" mu_viscous="16"/>
  </joint>
  <!-- sub-link defining detailed meshes for collision with environment -->
  <link name="panda_1_link3">
    <visual>
      <geometry>
        <mesh filename="package://franka_description/meshes/visual/link3.dae"/>
      </geometry>
    </visual>
    <collision>
      <geometry>
        <mesh filename="package://franka_description/meshes/collision/link3.stl"/>
      </geometry>
    </collision>
  </link>
  <!-- sub-link defining coarse geometries of real robot's internal self-collision -->
  <link name="panda_1_link3_sc">
    <collision>
      <origin rpy="0 0 0" xyz="0 0 -0.145"/>
      <geometry>
        <cylinder length="0.15" radius="0.06"/>
      </geometry>
    </collision>
    <collision>
      <origin xyz="0 0 -0.06999999999999999"/>
      <geometry>
        <sphere radius="0.06"/>
      </geometry>
    </collision>
    <collision>
      <origin xyz="0 0 -0.21999999999999997"/>
      <geometry>
        <sphere radius="0.06"/>
      </geometry>
    </collision>
  </link>
  <!-- fixed joint between both sub-links -->
  <joint name="panda_1_link3_sc_joint" type="fixed">
    <origin rpy="0 0 0"/>
    <parent link="panda_1_link3"/>
    <child link="panda_1_link3_sc"/>
  </joint>
  <joint name="panda_1_joint3" type="revolute">
    <origin rpy="1.5707963267948966 0 0" xyz="0 -0.316 0"/>
    <parent link="panda_1_link2"/>
    <child link="panda_1_link3"/>
    <axis xyz="0 0 1"/>
    <limit effort="87.0" lower="-2.8973" upper="2.8973" velocity="2.175"/>
    <safety_controller k_position="100.0" k_velocity="40.0" soft_lower_limit="-2.8973" soft_upper_limit="2.8973"/>
    <dynamics D="1" K="7000" damping="0.003" friction="0.0" mu_coulomb="0" mu_viscous="16"/>
  </joint>
  <!-- sub-link defining detailed meshes for collision with environment -->
  <link name="panda_1_link4">
    <visual>
      <geometry>
        <mesh filename="package://franka_description/meshes/visual/link4.dae"/>
      </geometry>
    </visual>
    <collision>
      <geometry>
        <mesh filename="package://franka_description/meshes/collision/link4.stl"/>
      </geometry>
    </collision>
  </link>
  <!-- sub-link defining coarse geometries of real robot's internal self-collision -->
  <link name="panda_1_link4_sc">
    <collision>
      <origin rpy="0 0 0" xyz="0 0 0"/>
      <geometry>
        <cylinder length="0.12" radius="0.06"/>
      </geometry>
    </collision>
    <collision>
      <origin xyz="0 0 0.06"/>
      <geometry>
        <sphere radius="0.06"/>
      </geometry>
    </collision>
    <collision>
      <origin xyz="0 0 -0.06"/>
      <geometry>
        <sphere radius="0.06"/>
      </geometry>
    </collision>
  </link>
  <!-- fixed joint between both sub-links -->
  <joint name="panda_1_link4_sc_joint" type="fixed">
    <origin rpy="0 0 0"/>
    <parent link="panda_1_link4"/>
    <child link="panda_1_link4_sc"/>
  </joint>
  <joint name="panda_1_joint4" type="revolute">
    <origin rpy="1.5707963267948966 0 0" xyz="0.0825 0 0"/>
    <parent link="panda_1_link3"/>
    <child link="panda_1_link4"/>
    <axis xyz="0 0 1"/>
    <limit effort="87.0" lower="-3.0718" upper="-0.0698" velocity="2.175"/>
    <safety_controller k_position="100.0" k_velocity="40.0" soft_lower_limit="-3.0718" soft_upper_limit="-0.0698"/>
    <dynamics D="1" K="7000" damping="0.003" friction="0.0" mu_coulomb="0" mu_viscous="16"/>
  </joint>
  <!-- sub-link defining detailed meshes for collision with environment -->
  <link name="panda_1_link5">
    <visual>
      <geometry>
        <mesh filename="package://franka_description/meshes/visual/link5.dae"/>
      </geometry>
    </visual>
    <collision>
      <geometry>
        <mesh filename="package://franka_description/meshes/collision/link5.stl"/>
      </geometry>
    </collision>
  </link>
  <!-- sub-link defining coarse geometries of real robot's internal self-collision -->
  <link name="panda_1_link5_sc">
    <collision>
      <origin rpy="0 0 0" xyz="0 0 -0.26"/>
      <geometry>
        <cylinder length="0.1" radius="0.06"/>
      </geometry>
    </collision>
    <collision>
      <origin xyz="0 0 -0.21000000000000002"/>
      <geometry>
        <sphere radius="0.06"/>
      </geometry>
    </collision>
    <collision>
      <origin xyz="0 0 -0.31"/>
      <geometry>
        <sphere radius="0.06"/>
      </geometry>
    </collision>
    <collision>
      <origin rpy="0 0 0.08" xyz="0 0.08 -0.13"/>
      <geometry>
        <cylinder length="0.14" radius="0.025"/>
      </geometry>
    </collision>
    <collision>
      <origin xyz="0 0.08 -0.06"/>
      <geometry>
        <sphere radius="0.025"/>
      </geometry>
    </collision>
    <collision>
      <origin xyz="0 0.08 -0.2"/>
      <geometry>
        <sphere radius="0.025"/>
      </geometry>
    </collision>
  </link>
  <!-- fixed joint between both sub-links -->
  <joint name="panda_1_link5_sc_joint" type="fixed">
    <origin rpy="0 0 0"/>
    <parent link="panda_1_link5"/>
    <child link="panda_1_link5_sc"/>
  </joint>
  <joint name="panda_1_joint5" type="revolute">
    <origin rpy="-1.5707963267948966 0 0" xyz="-0.0825 0.384 0"/>
    <parent link="panda_1_link4"/>
    <child link="panda_1_link5"/>
    <axis xyz="0 0 1"/>
    <limit effort="12.0" lower="-2.8973" upper="2.8973" velocity="2.61"/>
    <safety_controller k_position="100.0" k_velocity="40.0" soft_lower_limit="-2.8973" soft_upper_limit="2.8973"/>
    <dynamics D="1" K="7000" damping="0.003" friction="0.0" mu_coulomb="0" mu_viscous="16"/>
  </joint>
  <!-- sub-link defining detailed meshes for collision with environment -->
  <link name="panda_1_link6">
    <visual>
      <geometry>
        <mesh filename="package://franka_description/meshes/visual/link6.dae"/>
      </geometry>
    </visual>
    <collision>
      <geometry>
        <mesh filename="package://franka_description/meshes/collision/link6.stl"/>
      </geometry>
    </collision>
  </link>
  <!-- sub-link defining coarse geometries of real robot's internal self-collision -->
  <link name="panda_1_link6_sc">
    <collision>
      <origin rpy="0 0 0" xyz="0 0 -0.03"/>
      <geometry>
        <cylinder length="0.08" radius="0.05"/>
      </geometry>
    </collision>
    <collision>
      <origin xyz="0 0 0.010000000000000002"/>
      <geometry>
        <sphere radius="0.05"/>
      </geometry>
    </collision>
    <collision>
      <origin xyz="0 0 -0.07"/>
      <geometry>
        <sphere radius="0.05"/>
      </geometry>
    </collision>
  </link>
  <!-- fixed joint between both sub-links -->
  <joint name="panda_1_link6_sc_joint" type="fixed">
    <origin rpy="0 0 0"/>
    <parent link="panda_1_link6"/>
    <child link="panda_1_link6_sc"/>
  </joint>
  <joint name="panda_1_joint6" type="revolute">
    <origin rpy="1.5707963267948966 0 0" xyz="0 0 0"/>
    <parent link="panda_1_link5"/>
    <child link="panda_1_link6"/>
    <axis xyz="0 0 1"/>
    <limit effort="12.0" lower="-0.0175" upper="3.7525" velocity="2.61"/>
    <safety_controller k_position="100.0" k_velocity="40.0" soft_lower_limit="-0.0175" soft_upper_limit="3.7525"/>
    <dynamics D="1" K="7000" damping="0.003" friction="0.0" mu_coulomb="0" mu_viscous="16"/>
  </joint>
  <!-- sub-link defining detailed meshes for collision with environment -->
  <link name="panda_1_link7">
    <visual>
      <geometry>
        <mesh filename="package://franka_description/meshes/visual/link7.dae"/>
      </geometry>
    </visual>
    <collision>
      <geometry>
        <mesh filename="package://franka_description/meshes/collision/link7.stl"/>
      </geometry>
    </collision>
  </link>
  <!-- sub-link defining coarse geometries of real robot's internal self-collision -->
  <link name="panda_1_link7_sc">
    <collision>
      <origin rpy="0 0 0" xyz="0 0 0.01"/>
      <geometry>
        <cylinder length="0.14" radius="0.04"/>
      </geometry>
    </collision>
    <collision>
      <origin xyz="0 0 0.08"/>
      <geometry>
        <sphere radius="0.04"/>
      </geometry>
    </collision>
    <collision>
      <origin xyz="0 0 -0.060000000000000005"/>
      <geometry>
        <sphere radius="0.04"/>
      </geometry>
    </collision>
    <collision>
      <origin rpy="0 1.5707963267948966 0" xyz="0.06 0 0.082"/>
      <geometry>
        <cylinder length="0.01" radius="0.03"/>
      </geometry>
    </collision>
    <collision>
      <origin xyz="0.065 0 0.082"/>
      <geometry>
        <sphere radius="0.03"/>
      </geometry>
    </collision>
    <collision>
      <origin xyz="0.055 0 0.082"/>
      <geometry>
        <sphere radius="0.03"/>
      </geometry>
    </collision>
  </link>
  <!-- fixed joint between both sub-links -->
  <joint name="panda_1_link7_sc_joint" type="fixed">
    <origin rpy="0 0 0.7853981633974483"/>
    <parent link="panda_1_link7"/>
    <child link="panda_1_link7_sc"/>
  </joint>
  <joint name="panda_1_joint7" type="revolute">
    <origin rpy="1.5707963267948966 0 0" xyz="0.088 0 0"/>
    <parent link="panda_1_link6"/>
    <child link="panda_1_link7"/>
    <axis xyz="0 0 1"/>
    <limit effort="12.0" lower="-2.8973" upper="2.8973" velocity="2.61"/>
    <safety_controller k_position="100.0" k_velocity="40.0" soft_lower_limit="-2.8973" soft_upper_limit="2.8973"/>
    <dynamics D="1" K="7000" damping="0.003" friction="0.0" mu_coulomb="0" mu_viscous="16"/>
  </joint>
  <link name="panda_1_link8"/>
  <joint name="panda_1_joint8" type="fixed">
    <origin rpy="0 0 0" xyz="0 0 0.107"/>
    <parent link="panda_1_link7"/>
    <child link="panda_1_link8"/>
  </joint>
  <joint name="panda_1_ft_joint" type="fixed">
    <parent link="panda_1_link8"/>
    <child link="panda_1_ft"/>
    <origin rpy="0 0 -0.7853981633974483" xyz="0 0 0"/>
  </joint>
  <link name="panda_1_ft">
    <visual>
      <geometry>
        <mesh filename="package://mmint_franka_description/meshes/visual/gamma_insert.stl"/>
      </geometry>
      <material name="grey"/>
    </visual>
    <collision>
      <geometry>
        <mesh filename="package://mmint_franka_description/meshes/collision/gamma_insert.stl"/>
      </geometry>
    </collision>
  </link>
  <link name="panda_1_ft_origin"/>
  <joint name="panda_1_ft_origin_joint" type="fixed">
    <parent link="panda_1_ft"/>
    <child link="panda_1_ft_origin"/>
    <origin rpy="0 0 0" xyz="0 0 0.0408"/>
  </joint>
  <joint name="panda_1_hand_joint" type="fixed">
    <parent link="panda_1_ft_origin"/>
    <child link="panda_1_hand"/>
    <origin rpy="0 0 0" xyz="0 0 0.0079"/>
  </joint>
  <link name="panda_1_hand">
    <visual>
      <geometry>
        <mesh filename="package://franka_description/meshes/visual/hand.dae"/>
      </geometry>
    </visual>
    <collision>
      <geometry>
        <mesh filename="package://franka_description/meshes/collision/hand.stl"/>
      </geometry>
    </collision>
  </link>
  <!--  Left finger  -->
  <joint name="panda_1_finger_joint1" type="prismatic">
    <parent link="panda_1_hand"/>
    <child link="mount_left"/>
    <origin rpy="-1.5707963268 0 0" xyz="0 0 0.06340285"/>
    <axis xyz="0 0 1"/>
    <limit effort="100" lower="0" upper="0.04" velocity="0.2"/>
  </joint>
  <link name="mount_left">
    <visual>
      <origin rpy="3.1415926536 0 0" xyz="0.0 0.0 0.0"/>
      <geometry>
        <mesh filename="package://mmint_franka_description/meshes/visual/gelsight/panda_attach_gs_mini.obj"/>
      </geometry>
    </visual>
    <collision>
      <origin rpy="3.1415926536 0 0" xyz="0.0 0.0 0.0"/>
      <geometry>
        <mesh filename="package://mmint_franka_description/meshes/visual/gelsight/panda_attach_gs_mini.obj"/>
      </geometry>
    </collision>
  </link>
  <joint name="mount_joint_left" type="fixed">
    <parent link="mount_left"/>
    <child link="panda_1_leftfinger"/>
    <origin rpy="0 0 0" xyz="0.0 -0.02 0.0175"/>
  </joint>
  <link name="panda_1_leftfinger">
    <visual>
      <origin rpy="0 0 0" xyz="0 0 0"/>
      <geometry>
        <mesh filename="package://mmint_franka_description/meshes/visual/gelsight/panda_adapter_gsmini.obj"/>
      </geometry>
    </visual>
    <collision>
      <origin rpy="0 0 0" xyz="0.0 0.0 0.0"/>
      <geometry>
        <mesh filename="package://mmint_franka_description/meshes/visual/gelsight/panda_adapter_gsmini.obj"/>
      </geometry>
    </collision>
  </link>
  <joint name="panda_1_fingerbox_left_joint" type="fixed">
    <origin rpy="0 0 0" xyz="0.0 0.0 0.0"/>
    <parent link="panda_1_leftfinger"/>
    <child link="panda_1_fingerbox_left"/>
    <axis xyz="0 0 0"/>
  </joint>
  <link name="panda_1_fingerbox_left">
    <visual>
      <geometry>
        <mesh filename="package://mmint_franka_description/meshes/visual/gelsight/gsmini_shell_hollow_transformed.obj"/>
      </geometry>
    </visual>
    <collision>
      <geometry>
        <mesh filename="package://mmint_franka_description/meshes/visual/gelsight/gsmini_shell_hollow_transformed.obj"/>
      </geometry>
    </collision>
  </link>
  <joint name="elastomer_joint_left" type="fixed">
    <origin rpy="0 0 0" xyz="0.0 0.0 0.0"/>
    <parent link="panda_1_fingerbox_left"/>
    <child link="elastomer_left"/>
    <axis xyz="0 0 0"/>
  </joint>
  <link name="elastomer_left">
    <visual>
      <geometry>
        <mesh filename="package://mmint_franka_description/meshes/visual/gelsight/gsmini_elastomer_transformed_both_sides.obj"/>
      </geometry>
    </visual>
    <collision>
      <geometry>
        <mesh filename="package://mmint_franka_description/meshes/visual/gelsight/gsmini_elastomer_transformed_enclosed.obj"/>
      </geometry>
    </collision>
  </link>
  <joint name="elastomer_tip_joint_left" type="fixed">
    <!-- <origin rpy="1.5707963267948966 0 0" xyz="0.0 -0.00255914 0.06776"/>  -->
    <origin rpy="3.141592653589793 0 0" xyz="-0.00050001 -0.05975001 -0.01125"/>
    <parent link="panda_1_fingerbox_left"/>
    <child link="elastomer_tip_left"/>
    <axis xyz="0 0 0"/>
  </joint>
  <link name="elastomer_tip_left"/>
  <joint name="panda_1_fingertip_joint1" type="fixed">
    <parent link="panda_1_fingerbox_left"/>
    <child link="panda_1_leftfingertip"/>
    <!--0.08388700 (franka_finger_length)-->
    <origin rpy="0 0 0" xyz="0 -0.07388700 0"/>
  </joint>
  <link name="panda_1_leftfingertip"/>
  <!--  Right finger  -->
  <joint name="panda_1_finger_joint2" type="prismatic">
    <parent link="panda_1_hand"/>
    <child link="mount_right"/>
    <origin rpy="-1.5707 0 3.1415926536" xyz="0 0 0.06340285"/>
    <axis xyz="0 0 1"/>
    <limit effort="100" lower="0.0" upper="0.04" velocity="0.2"/>
  </joint>
  <link name="mount_right">
    <visual>
      <origin rpy="3.1415926536 0 0" xyz="0.0 0.0 0.0"/>
      <geometry>
        <mesh filename="package://mmint_franka_description/meshes/visual/gelsight/panda_attach_gs_mini.obj"/>
      </geometry>
    </visual>
    <collision>
      <origin rpy="3.1415926536 0 0" xyz="0.0 0.0 0.0"/>
      <geometry>
        <mesh filename="package://mmint_franka_description/meshes/visual/gelsight/panda_attach_gs_mini.obj"/>
      </geometry>
    </collision>
  </link>
  <joint name="mount_joint_right" type="fixed">
    <origin rpy="0 0 0" xyz="0.0 -0.02 0.0175"/>
    <parent link="mount_right"/>
    <child link="panda_1_rightfinger"/>
    <axis xyz="0 0 0"/>
  </joint>
  <link name="panda_1_rightfinger">
    <visual>
      <origin rpy="0 0 0" xyz="0.0 0.0 0.0"/>
      <geometry>
        <mesh filename="package://mmint_franka_description/meshes/visual/gelsight/panda_adapter_gsmini.obj"/>
      </geometry>
    </visual>
    <collision>
      <origin rpy="0 0 0" xyz="0.0 0.0 0.0"/>
      <geometry>
        <mesh filename="package://mmint_franka_description/meshes/visual/gelsight/panda_adapter_gsmini.obj"/>
      </geometry>
    </collision>
  </link>
  <joint name="panda_1_fingerbox_right_joint" type="fixed">
    <origin rpy="0 0 0" xyz="0.0 0.0 0.0"/>
    <parent link="panda_1_rightfinger"/>
    <child link="panda_1_fingerbox_right"/>
    <axis xyz="0 0 0"/>
  </joint>
  <link name="panda_1_fingerbox_right">
    <visual>
      <geometry>
        <mesh filename="package://mmint_franka_description/meshes/visual/gelsight/gsmini_shell_hollow_transformed.obj"/>
      </geometry>
    </visual>
    <collision>
      <geometry>
        <mesh filename="package://mmint_franka_description/meshes/visual/gelsight/gsmini_shell_hollow_transformed.obj"/>
      </geometry>
    </collision>
  </link>
  <joint name="elastomer_joint_right" type="fixed">
    <origin rpy="0 0 0" xyz="0.0 0.0 0.0"/>
    <parent link="panda_1_rightfinger"/>
    <child link="elastomer_right"/>
    <axis xyz="0 0 0"/>
  </joint>
  <link name="elastomer_right">
    <!-- surface tip of the elastomer  -->
    <visual>
      <geometry>
        <mesh filename="package://mmint_franka_description/meshes/visual/gelsight/gsmini_elastomer_transformed_both_sides.obj"/>
      </geometry>
    </visual>
    <collision>
      <geometry>
        <mesh filename="package://mmint_franka_description/meshes/visual/gelsight/gsmini_elastomer_transformed_enclosed.obj"/>
      </geometry>
    </collision>
  </link>
  <joint name="elastomer_tip_joint_right" type="fixed">
    <!-- <origin rpy="1.5707963267948966 0 0" xyz="0.0 -0.00255914 0.06776"/> -->
    <origin rpy="3.141592653589793 0 0" xyz="-0.00050001 -0.05975001 -0.01125"/>
    <parent link="panda_1_fingerbox_right"/>
    <child link="elastomer_tip_right"/>
    <axis xyz="0 0 0"/>
  </joint>
  <link name="elastomer_tip_right"/>
  <joint name="panda_1_fingertip_joint2" type="fixed">
    <parent link="panda_1_fingerbox_right"/>
    <child link="panda_1_rightfingertip"/>
    <!--0.08388700 (franka_finger_length)-->
    <origin rpy="0 0 0" xyz="0 -0.07388700 0"/>
  </joint>
  <link name="panda_1_rightfingertip"/>
  <!-- Grasp center -->
  <joint name="panda_1_fingertip_centered_joint" type="fixed">
    <parent link="panda_1_hand"/>
    <child link="grasp_frame"/>
    <origin rpy="0 0 0" xyz="0 0 0.14315286"/>
  </joint>
  <link name="grasp_frame"/>
</robot>

